ERROR 2021-07-04 16:47:17,511 log 29272 33740 Internal Server Error: /travel/risk_area
Traceback (most recent call last):
  File "C:\Users\wangzhen\miniconda3\envs\django\lib\site-packages\django\db\backends\utils.py", line 84, in _execute
    return self.cursor.execute(sql, params)
  File "C:\Users\wangzhen\miniconda3\envs\django\lib\site-packages\django\db\backends\mysql\base.py", line 73, in execute
    return self.cursor.execute(query, args)
  File "C:\Users\wangzhen\miniconda3\envs\django\lib\site-packages\MySQLdb\cursors.py", line 206, in execute
    res = self._query(query)
  File "C:\Users\wangzhen\miniconda3\envs\django\lib\site-packages\MySQLdb\cursors.py", line 319, in _query
    db.query(q)
  File "C:\Users\wangzhen\miniconda3\envs\django\lib\site-packages\MySQLdb\connections.py", line 259, in query
    _mysql.connection.query(self, query)
MySQLdb._exceptions.ProgrammingError: (1146, "Table 'marcovdb.risk_riskarea' doesn't exist")

The above exception was the direct cause of the following exception:

Traceback (most recent call last):
  File "C:\Users\wangzhen\miniconda3\envs\django\lib\site-packages\django\core\handlers\exception.py", line 47, in inner
    response = get_response(request)
  File "C:\Users\wangzhen\miniconda3\envs\django\lib\site-packages\django\core\handlers\base.py", line 179, in _get_response
    response = wrapped_callback(request, *callback_args, **callback_kwargs)
  File "C:\Users\wangzhen\miniconda3\envs\django\lib\site-packages\django\views\generic\base.py", line 70, in view
    return self.dispatch(request, *args, **kwargs)
  File "C:\Users\wangzhen\miniconda3\envs\django\lib\site-packages\django\views\generic\base.py", line 98, in dispatch
    return handler(request, *args, **kwargs)
  File "C:\Users\wangzhen\gitee-marcov-backend\utils\meta_wrapper.py", line 58, in wrapper
    raise e
  File "C:\Users\wangzhen\gitee-marcov-backend\utils\meta_wrapper.py", line 50, in wrapper
    values = req_func(*args, **kw)
  File "C:\Users\wangzhen\gitee-marcov-backend\risk\views.py", line 12, in get
    for area in area_list:
  File "C:\Users\wangzhen\miniconda3\envs\django\lib\site-packages\django\db\models\query.py", line 287, in __iter__
    self._fetch_all()
  File "C:\Users\wangzhen\miniconda3\envs\django\lib\site-packages\django\db\models\query.py", line 1308, in _fetch_all
    self._result_cache = list(self._iterable_class(self))
  File "C:\Users\wangzhen\miniconda3\envs\django\lib\site-packages\django\db\models\query.py", line 53, in __iter__
    results = compiler.execute_sql(chunked_fetch=self.chunked_fetch, chunk_size=self.chunk_size)
  File "C:\Users\wangzhen\miniconda3\envs\django\lib\site-packages\django\db\models\sql\compiler.py", line 1156, in execute_sql
    cursor.execute(sql, params)
  File "C:\Users\wangzhen\miniconda3\envs\django\lib\site-packages\django\db\backends\utils.py", line 98, in execute
    return super().execute(sql, params)
  File "C:\Users\wangzhen\miniconda3\envs\django\lib\site-packages\django\db\backends\utils.py", line 66, in execute
    return self._execute_with_wrappers(sql, params, many=False, executor=self._execute)
  File "C:\Users\wangzhen\miniconda3\envs\django\lib\site-packages\django\db\backends\utils.py", line 75, in _execute_with_wrappers
    return executor(sql, params, many, context)
  File "C:\Users\wangzhen\miniconda3\envs\django\lib\site-packages\django\db\backends\utils.py", line 84, in _execute
    return self.cursor.execute(sql, params)
  File "C:\Users\wangzhen\miniconda3\envs\django\lib\site-packages\django\db\utils.py", line 90, in __exit__
    raise dj_exc_value.with_traceback(traceback) from exc_value
  File "C:\Users\wangzhen\miniconda3\envs\django\lib\site-packages\django\db\backends\utils.py", line 84, in _execute
    return self.cursor.execute(sql, params)
  File "C:\Users\wangzhen\miniconda3\envs\django\lib\site-packages\django\db\backends\mysql\base.py", line 73, in execute
    return self.cursor.execute(query, args)
  File "C:\Users\wangzhen\miniconda3\envs\django\lib\site-packages\MySQLdb\cursors.py", line 206, in execute
    res = self._query(query)
  File "C:\Users\wangzhen\miniconda3\envs\django\lib\site-packages\MySQLdb\cursors.py", line 319, in _query
    db.query(q)
  File "C:\Users\wangzhen\miniconda3\envs\django\lib\site-packages\MySQLdb\connections.py", line 259, in query
    _mysql.connection.query(self, query)
django.db.utils.ProgrammingError: (1146, "Table 'marcovdb.risk_riskarea' doesn't exist")
